<?xml version="1.0" encoding="utf-8"?>
<!-- This URDF was automatically created by SolidWorks to URDF Exporter! Originally created by Stephen Brawner (brawner@gmail.com) 
     Commit Version: 1.5.1-0-g916b5db  Build Version: 1.5.7152.31018
     For more information, please see http://wiki.ros.org/sw_urdf_exporter -->
<robot
  name="marm" xmlns:xacro="http://www.ros.org/wiki/xacro">
<link name="base_link">
    <inertial>
      <origin xyz="-0.069332994460208 0.00159168387635345 0.0653887866392719" rpy="0 0 0" />
      <mass value="2.33550924194226" />
      <inertia  ixx="0.0099328731586153"  ixy="3.62130593535287E-06"   ixz="-0.00104555810393269"   iyy="0.00497792027172909"   iyz="6.12890883113497E-07"   izz="0.0121809615610289" />
    </inertial>
    <visual>
      <origin  xyz="0 0 0"  rpy="0 0 0" />
      <geometry>
        <mesh  filename="package://marm_base/meshes/c/base_link.STL" />
      </geometry>
      <material  name="">
        <color  rgba="0.792156862745098 0.819607843137255 0.933333333333333 1" />
      </material>
    </visual>
    <collision>
      <origin xyz="0 0 0" rpy="0 0 0" />
      <geometry>
        <mesh filename="package://marm_base/meshes/c/base_link.STL" />
      </geometry>
    </collision>
  </link>

<link name="link_1">
    <inertial>
      <origin xyz="0 0 -0.00101102878492629"  rpy="0 0 0" />
      <mass value="0.134028102660835" />
      <inertia ixx="7.13099731122913E-05" ixy="1.17771253350979E-21" ixz="2.40976141297024E-21"  iyy="7.13099731122913E-05"  iyz="-1.20943874309478E-21"  izz="0.000109865960683711" />
    </inertial>
    <visual>
      <origin xyz="0 0 0" rpy="0 0 0" />
      <geometry>
        <mesh  filename="package://marm_base/meshes/c/link_1.STL" />
      </geometry>
      <material  name="">
        <color rgba="0.792156862745098 0.819607843137255 0.933333333333333 1" />
      </material>
    </visual>
    <collision>
      <origin xyz="0 0 0" rpy="0 0 0" />
      <geometry>
        <mesh  filename="package://marm_base/meshes/c/link_1.STL" />
      </geometry>
    </collision>
  </link>
<joint name="joint_1" type="continuous">
    <origin  xyz="0.10653 -0.098216 -0.1"  rpy="1.5708 0 0" />
    <parent  link="base_link" />
    <child  link="link_1" />
    <axis xyz="0 0 -1" />
  </joint>
<link name="link_2">
    <inertial>
      <origin  xyz="0 0 -0.00101102878492629"   rpy="0 0 0" />
      <mass  value="0.134028102660835" />
      <inertia ixx="7.13099731122913E-05" ixy="1.17752320689254E-21"  ixz="2.43988203833033E-21"  iyy="7.13099731122913E-05"  iyz="-6.47128446607132E-22" izz="0.000109865960683711" />
    </inertial>
    <visual>
      <origin xyz="0 0 0"  rpy="0 0 0" />
      <geometry>
        <mesh filename="package://marm_base/meshes/c/link_2.STL" />
      </geometry>
      <material name="">
        <color rgba="0.792156862745098 0.819607843137255 0.933333333333333 1" />
      </material>
    </visual>
    <collision>
      <origin xyz="0 0 0" rpy="0 0 0" />
      <geometry>
        <mesh  filename="package://marm_base/meshes/c/link_2.STL" />
      </geometry>
    </collision>
  </link>
<joint  name="joint_2"  type="continuous">
    <origin xyz="0.10653 0.098216 -0.1"  rpy="1.5708 0 3.1416" />
    <parent  link="base_link" />
    <child  link="link_2" />
    <axis  xyz="0 0 -1" />
  </joint>
<link name="link_3">
    <inertial>
      <origin  xyz="1.38777878078145E-17 0 -0.00101102878492629"  rpy="0 0 0" />
      <mass   value="0.134028102660835" />
      <inertia  ixx="7.13099731122913E-05"   ixy="1.17757369399048E-21" ixz="2.39149875275608E-21" iyy="7.13099731122913E-05" iyz="-5.2892272939433E-22" izz="0.000109865960683711" />
    </inertial>
    <visual>
      <origin xyz="0 0 0" rpy="0 0 0" />
      <geometry>
        <mesh filename="package://marm_base/meshes/c/link_3.STL" />
      </geometry>
      <material name="">
        <color  rgba="0.792156862745098 0.819607843137255 0.933333333333333 1" />
      </material>
    </visual>
    <collision>
      <origin xyz="0 0 0" rpy="0 0 0" />
      <geometry>
        <mesh filename="package://marm_base/meshes/c/link_3.STL" />
      </geometry>
    </collision>
  </link>
<joint  name="joint_3" type="continuous">
    <origin xyz="-0.1054579162598 -0.0982163407908 -0.1"  rpy="1.5707963267949 0 0" />
    <parent link="base_link" />
    <child link="link_3" />
    <axis  xyz="0 0 -1" />
  </joint>
<link name="link_4">
    <inertial>
      <origin  xyz="-1.38777878078145E-17 0 -0.00101102878492629"  rpy="0 0 0" />
      <mass value="0.134028102660835" />
      <inertia ixx="7.13099731122913E-05" ixy="1.17763680286289E-21" ixz="2.39598028827714E-21"   iyy="7.13099731122913E-05" iyz="-1.14719127566941E-21"  izz="0.000109865960683711" />
    </inertial>
    <visual>
      <origin xyz="0 0 0"  rpy="0 0 0" />
      <geometry>
        <mesh   filename="package://marm_base/meshes/c/link_4.STL" />
      </geometry>
      <material  name="">
        <color  rgba="0.792156862745098 0.819607843137255 0.933333333333333 1" />
      </material>
    </visual>
    <collision>
      <origin xyz="0 0 0" rpy="0 0 0" />
      <geometry>
        <mesh  filename="package://marm_base/meshes/c/link_4.STL" />
      </geometry>
    </collision>
  </link>
<joint  name="joint_4" type="continuous">
    <origin xyz="-0.10546 0.098216 -0.1"   rpy="1.5708 0 3.1416" />
    <parent link="base_link" />
    <child link="link_4" />
    <axis  xyz="0 0 -1" />
  </joint>
<link  name="link_5">
    <inertial>
      <origin  xyz="-0.000102737325545804 -0.0229999910083138 0.0373923165167594"   rpy="0 0 0" />
      <mass  value="0.0459980877240432" />
      <inertia  ixx="3.70020626967E-05"  ixy="-2.93743683504277E-13"   ixz="4.14494818687051E-08"   iyy="7.11271492032382E-06"   iyz="9.3759002706371E-12"  izz="3.30321009897597E-05" />
    </inertial>
    <visual>
      <origin   xyz="0 0 0" rpy="0 0 0" />
      <geometry>
        <mesh  filename="package://marm_base/meshes/c/link_5.STL" />
      </geometry>
      <material name="">
        <color  rgba="0.792156862745098 0.819607843137255 0.933333333333333 1" />
      </material>
    </visual>
    <collision>
      <origin  xyz="0 0 0"  rpy="0 0 0" />
      <geometry>
        <mesh filename="package://marm_base/meshes/c/link_5.STL" />
      </geometry>
    </collision>
  </link>
<joint name="joint_5" type="continuous">
    <origin  xyz="0.1554035339355 0.025507624634405 0.016"  rpy="0 0 0" />
    <parent  link="base_link" />
    <child  link="link_5" />
    <axis   xyz="0 1 0" />
  </joint>



<link name="arm_base_link">
    <inertial>
      <origin xyz="0.00061667 0.00034699 0.035058" rpy="0 0 0" />
      <mass value="0.062585" />
      <inertia ixx="2.1158E-05" ixy="1.3819E-10" ixz="-1.5206E-07" iyy="1.6483E-05"  iyz="-6.5712E-09" izz="2.7121E-05" />
    </inertial>
    <visual>
      <origin xyz="0 0 0" rpy="0 0 0" />
      <geometry>
        <mesh  filename="package://marm_base/meshes/b/base_link.stl" />
      </geometry>
      <material name="">
        <color rgba="0.79216 0.81961 0.93333 1" />
      </material>
    </visual>
    <collision>
      <origin xyz="0 0 0" rpy="0 0 0" />
      <geometry>
        <mesh filename="package://marm_base/meshes/b/base_link.stl" />
      </geometry>
    </collision>
  </link>

<link name="arm_link_1">
    <inertial>
      <origin xyz="-0.0005411 -0.010002 0.014716"  rpy="0 0 0" />
      <mass value="0.04138" />
      <inertia ixx="7.5324E-06"  ixy="6.5712E-09" ixz="1.5271E-07" iyy="6.6408E-06" iyz="-1.3829E-10" izz="1.1356E-05" />
    </inertial>
    <visual>
      <origin xyz="0 0 0" rpy="0 0 0" />
      <geometry>
        <mesh filename="package://marm_base/meshes/b/link_1.stl" />
      </geometry>
      <material name="">
        <color  rgba="0.79216 0.81961 0.93333 1" />
      </material>
    </visual>
    <collision>
      <origin  xyz="0 0 0"  rpy="0 0 0" />
      <geometry>
        <mesh filename="package://marm_base/meshes/b/link_1.stl" />
      </geometry>
    </collision>
  </link>

<link name="arm_link_2">
    <inertial>
      <origin xyz="-0.0214593761328952 0.000392266144239384 0.0519716472176175"  rpy="0 0 0" />
      <mass value="0.019785178685304" />
      <inertia ixx="7.24517690784899E-06" ixy="-5.08946034245922E-15" ixz="-2.03540651583669E-13" iyy="1.5786928392671E-05" iyz="-4.33327883494802E-08"  izz="1.03552306916003E-05" />
    </inertial>
    <visual>
      <origin xyz="0 0 0"  rpy="0 0 0" />
      <geometry>
        <mesh  filename="package://marm_base/meshes/b/link_2.stl" />
      </geometry>
      <material name="">
        <color  rgba="0.792156862745098 0.819607843137255 0.933333333333333 1" />
      </material>
    </visual>
    <collision>
      <origin xyz="0 0 0" rpy="0 0 0" />
      <geometry>
        <mesh filename="package://marm_base/meshes/b/link_2.stl" />
      </geometry>
    </collision>
  </link>

<link name="arm_link_3">
    <inertial>
      <origin xyz="-0.0248973946943435 -0.000606800174536338 0.0228956824379924" rpy="0 0 0" />
      <mass value="0.0524190047350437" />
      <inertia ixx="1.1603913199014E-05"  ixy="1.52191520868279E-07"   ixz="1.3509620232988E-09"  iyy="1.96400234319581E-05" iyz="-3.88327570885192E-07"  izz="1.210333485627E-05" />
    </inertial>
    <visual>
      <origin  xyz="0 0 0" rpy="0 0 0" />
      <geometry>
        <mesh filename="package://marm_base/meshes/b/link_3.stl" />
      </geometry>
      <material  name="">
        <color  rgba="0.792156862745098 0.819607843137255 0.933333333333333 1" />
      </material>
    </visual>
    <collision>
      <origin  xyz="0 0 0"   rpy="0 0 0" />
      <geometry>
        <mesh filename="package://marm_base/meshes/b/link_3.stl" />
      </geometry>
    </collision>
  </link>

<link name="arm_link_4">
    <inertial>
 <origin xyz="-0.0246619937110533 0.0101669008822505 0.0194479624423403" rpy="0 0 0" />
      <mass value="0.0790420323885757" />
      <inertia ixx="1.88108148303716E-05" ixy="6.70386689814524E-09" ixz="-2.7330082098613E-10" iyy="1.32224319979645E-05" iyz="2.34209004916344E-07" izz="1.8800512562106E-05" />
    </inertial>
    <visual>
      <origin  xyz="0 0 0" rpy="0 0 0" />
      <geometry>
        <mesh  filename="package://marm_base/meshes/b/link_4.stl" />
      </geometry>
      <material name="">
        <color  rgba="0.792156862745098 0.819607843137255 0.933333333333333 1" />
      </material>
    </visual>
    <collision>
      <origin  xyz="0 0 0"  rpy="0 0 0" />
      <geometry>
        <mesh  filename="package://marm_base/meshes/b/link_4.stl" />
      </geometry>
    </collision>
  </link>

<link name="arm_link_5">
    <inertial>
      <origin xyz="-0.00466405410073303 -0.000922546265514259 0.0440761448135507"  rpy="0 0 0" />
      <mass  value="0.0960706538751792" />
      <inertia ixx="8.75397961621591E-05"  ixy="5.56761137493007E-08"  ixz="6.4543893895328E-07"  iyy="4.43721865945793E-05" iyz="1.8163572909913E-06"  izz="5.58483997223978E-05" />
    </inertial>
    <visual>
      <origin xyz="0 0 0" rpy="0 0 0" />
      <geometry>
        <mesh  filename="package://marm_base/meshes/b/link_5.stl" />
      </geometry>
      <material  name="">
        <color  rgba="0.792156862745098 0.819607843137255 0.933333333333333 1" />
      </material>
    </visual>
    <collision>
      <origin xyz="0 0 0" rpy="0 0 0" />
      <geometry>
        <mesh  filename="package://marm_base/meshes/b/link_5.stl" />
      </geometry>
    </collision>
  </link>

<link name="tool0"/>

<!--0.085 -0.01 Important parameters-->
<joint name="arm_joint_1" type="revolute">
    <origin rpy="0 0 0" xyz="0.085 -0.01 0.18"/>
    <parent link="base_link" />
    <child  link="arm_link_1" />
    <axis xyz="0 0 1" />
	<limit effort="2.5" velocity="3.49" lower="-1.57" upper="1.57" />
  </joint>
<!---0.01 0.019 Important parameters-->
<joint name="arm_joint_2" type="revolute">
    <origin rpy="0 0 0" xyz="-0.01 0.015 0.019"/>
    <parent link="arm_link_1" />
    <child link="arm_link_2" />
    <axis xyz="0 1 0" />
	<limit effort="2.5" velocity="3.49" lower="-0.785" upper="2.35619" />
  </joint>
<!--0.103 Important parameters-->
<joint name="arm_joint_3" type="revolute">
    <origin rpy="0 0 0" xyz="0 0 0.103"/>  
    <parent link="arm_link_2" />
    <child link="arm_link_3" />
    <axis xyz="0 1 0" />
	<limit effort="2.5" velocity="3.49" lower="-2.35619" upper="2.35619" />
  </joint>
<!--0.098 Important parameters-->
<joint name="arm_joint_4" type="revolute">
    <origin rpy="0 0 0" xyz="0 0 0.098"/>
    <parent link="arm_link_3" />
    <child link="arm_link_4" />
    <axis  xyz="0 1 0" />
	<limit effort="2.5" velocity="3.49" lower="-2.35619" upper="2.35619" />
  </joint>
<!--0.063 Important parameters-->
<joint name="arm_joint_5" type="revolute">
    <origin rpy="0 0 0" xyz="0 0 0.063"/>
    <parent  link="arm_link_4" />
    <child link="arm_link_5" />
    <axis xyz="0 0 1" />
	<limit effort="2.5" velocity="3.49" lower="-1.57" upper="1.57" />
  </joint>

<joint name="joint_5-tool0" type="fixed">
	<parent link="arm_link_5"/>
	<child link="tool0"/>
	<origin rpy="0 -1.570796327 0" xyz="0 0 0.08"/>
  </joint>

<joint name="arm_base_joint" type="fixed">
    <origin rpy="0 0 0" xyz="0.08455 0 0.104"  />
    <parent link="base_link" />
    <child link="arm_base_link" />
  </joint>


   <!-- Transmissions for ROS Control -->
<xacro:macro name="transmission_block" params="joint_name">
    <transmission name="tran1">
      <type>transmission_interface/SimpleTransmission</type>
      <joint name="${joint_name}">
        <hardwareInterface>hardware_interface/PositionJointInterface</hardwareInterface>
      </joint>
      <actuator name="motor1">
        <hardwareInterface>hardware_interface/PositionJointInterface</hardwareInterface>
        <mechanicalReduction>1</mechanicalReduction>
      </actuator>
    </transmission>
  </xacro:macro>
  
  <xacro:transmission_block joint_name="arm_joint_1"/>
  <xacro:transmission_block joint_name="arm_joint_2"/>
  <xacro:transmission_block joint_name="arm_joint_3"/>
  <xacro:transmission_block joint_name="arm_joint_4"/>
  <xacro:transmission_block joint_name="arm_joint_5"/>
  <xacro:transmission_block joint_name="arm_joint_6"/>

  <!-- ros_control plugin -->
  <gazebo>
    <plugin name="gazebo_ros_control" filename="libgazebo_ros_control.so">
      <robotNamespace>/marm_base</robotNamespace>
    </plugin>
  </gazebo>
  
</robot>
